<?xml version="1.0"?>
<robot name="quadruped_robot">
    <!-- Base Link -->
    <link name="base_link">
        <visual>
            <geometry>
                <box size="0.4 0.4 0.2"/>
            </geometry>
            <material name="blue">
                <color rgba="0 0 0.8 1"/>
            </material>
        </visual>
        <collision>
            <geometry>
                <box size="0.4 0.4 0.2"/>
            </geometry>
        </collision>
        <inertial>
            <mass value="5"/>
            <inertia ixx="0.1" ixy="0" ixz="0" iyy="0.1" iyz="0" izz="0.1"/>
        </inertial>
    </link>

    <!-- Front Left Leg -->
    <link name="front_left_upper">
        <visual>
            <geometry>
                <box size="0.1 0.1 0.3"/>
            </geometry>
            <material name="red">
                <color rgba="0.8 0 0 1"/>
            </material>
        </visual>
        <collision>
            <geometry>
                <box size="0.1 0.1 0.3"/>
            </geometry>
        </collision>
        <inertial>
            <mass value="1"/>
            <inertia ixx="0.01" ixy="0" ixz="0" iyy="0.01" iyz="0" izz="0.01"/>
        </inertial>
    </link>

    <joint name="front_left_hip" type="revolute">
        <parent link="base_link"/>
        <child link="front_left_upper"/>
        <origin xyz="0.2 0.2 0.0" rpy="0 0 0"/>
        <axis xyz="0 0 1"/>
        <limit lower="-0.5" upper="0.5" effort="100" velocity="10"/>
    </joint>

    <link name="front_left_lower">
        <visual>
            <geometry>
                <box size="0.1 0.1 0.3"/>
            </geometry>
            <material name="green">
                <color rgba="0 0.8 0 1"/>
            </material>
        </visual>
        <collision>
            <geometry>
                <box size="0.1 0.1 0.3"/>
            </geometry>
        </collision>
        <inertial>
            <mass value="1"/>
            <inertia ixx="0.01" ixy="0" ixz="0" iyy="0.01" iyz="0" izz="0.01"/>
        </inertial>
    </link>

    <joint name="front_left_knee" type="revolute">
        <parent link="front_left_upper"/>
        <child link="front_left_lower"/>
        <origin xyz="0 0 -0.3" rpy="0 0 0"/>
        <axis xyz="0 1 0"/>
        <limit lower="-1.0" upper="0" effort="100" velocity="10"/>
    </joint>

    <!-- Front Right Leg -->
    <link name="front_right_upper">
        <visual>
            <geometry>
                <box size="0.1 0.1 0.3"/>
            </geometry>
            <material name="red">
                <color rgba="0.8 0 0 1"/>
            </material>
        </visual>
        <collision>
            <geometry>
                <box size="0.1 0.1 0.3"/>
            </geometry>
        </collision>
        <inertial>
            <mass value="1"/>
            <inertia ixx="0.01" ixy="0" ixz="0" iyy="0.01" iyz="0" izz="0.01"/>
        </inertial>
    </link>

    <joint name="front_right_hip" type="revolute">
        <parent link="base_link"/>
        <child link="front_right_upper"/>
        <origin xyz="0.2 -0.2 0.0" rpy="0 0 0"/>
        <axis xyz="0 0 1"/>
        <limit lower="-0.5" upper="0.5" effort="100" velocity="10"/>
    </joint>

    <link name="front_right_lower">
        <visual>
            <geometry>
                <box size="0.1 0.1 0.3"/>
            </geometry>
            <material name="green">
                <color rgba="0 0.8 0 1"/>
            </material>
        </visual>
        <collision>
            <geometry>
                <box size="0.1 0.1 0.3"/>
            </geometry>
        </collision>
        <inertial>
            <mass value="1"/>
            <inertia ixx="0.01" ixy="0" ixz="0" iyy="0.01" iyz="0" izz="0.01"/>
        </inertial>
    </link>

    <joint name="front_right_knee" type="revolute">
        <parent link="front_right_upper"/>
        <child link="front_right_lower"/>
        <origin xyz="0 0 -0.3" rpy="0 0 0"/>
        <axis xyz="0 1 0"/>
        <limit lower="-1.0" upper="0" effort="100" velocity="10"/>
    </joint>

    <!-- Back Left Leg -->
    <link name="back_left_upper">
        <visual>
            <geometry>
                <box size="0.1 0.1 0.3"/>
            </geometry>
            <material name="red">
                <color rgba="0.8 0 0 1"/>
            </material>
        </visual>
        <collision>
            <geometry>
                <box size="0.1 0.1 0.3"/>
            </geometry>
        </collision>
        <inertial>
            <mass value="1"/>
            <inertia ixx="0.01" ixy="0" ixz="0" iyy="0.01" iyz="0" izz="0.01"/>
        </inertial>
    </link>

    <joint name="back_left_hip" type="revolute">
        <parent link="base_link"/>
        <child link="back_left_upper"/>
        <origin xyz="-0.2 0.2 0.0" rpy="0 0 0"/>
        <axis xyz="0 0 1"/>
        <limit lower="-0.5" upper="0.5" effort="100" velocity="10"/>
    </joint>

    <link name="back_left_lower">
        <visual>
            <geometry>
                <box size="0.1 0.1 0.3"/>
            </geometry>
            <material name="green">
                <color rgba="0 0.8 0 1"/>
            </material>
        </visual>
        <collision>
            <geometry>
                <box size="0.1 0.1 0.3"/>
            </geometry>
        </collision>
        <inertial>
            <mass value="1"/>
            <inertia ixx="0.01" ixy="0" ixz="0" iyy="0.01" iyz="0" izz="0.01"/>
        </inertial>
    </link>

    <joint name="back_left_knee" type="revolute">
        <parent link="back_left_upper"/>
        <child link="back_left_lower"/>
        <origin xyz="0 0 -0.3" rpy="0 0 0"/>
        <axis xyz="0 1 0"/>
        <limit lower="-1.0" upper="0" effort="100" velocity="10"/>
    </joint>

    <!-- Back Right Leg -->
    <link name="back_right_upper">
        <visual>
            <geometry>
                <box size="0.1 0.1 0.3"/>
            </geometry>
            <material name="red">
                <color rgba="0.8 0 0 1"/>
            </material>
        </visual>
        <collision>
            <geometry>
                <box size="0.1 0.1 0.3"/>
            </geometry>
        </collision>
        <inertial>
            <mass value="1"/>
            <inertia ixx="0.01" ixy="0" ixz="0" iyy="0.01" iyz="0" izz="0.01"/>
        </inertial>
    </link>

    <joint name="back_right_hip" type="revolute">
        <parent link="base_link"/>
        <child link="back_right_upper"/>
        <origin xyz="-0.2 -0.2 0.0" rpy="0 0 0"/>
        <axis xyz="0 0 1"/>
        <limit lower="-0.5" upper="0.5" effort="100" velocity="10"/>
    </joint>

    <link name="back_right_lower">
        <visual>
            <geometry>
                <box size="0.1 0.1 0.3"/>
            </geometry>
            <material name="green">
                <color rgba="0 0.8 0 1"/>
            </material>
        </visual>
        <collision>
            <geometry>
                <box size="0.1 0.1 0.3"/>
            </geometry>
        </collision>
        <inertial>
            <mass value="1"/>
            <inertia ixx="0.01" ixy="0" ixz="0" iyy="0.01" iyz="0" izz="0.01"/>
        </inertial>
    </link>

    <joint name="back_right_knee" type="revolute">
        <parent link="back_right_upper"/>
        <child link="back_right_lower"/>
        <origin xyz="0 0 -0.3" rpy="0 0 0"/>
        <axis xyz="0 1 0"/>
        <limit lower="-1.0" upper="0" effort="100" velocity="10"/>
    </joint>
</robot> 